#VRML_SIM R2021a utf8
WorldInfo {
  coordinateSystem "NUE"
}
Viewpoint {
  orientation 0.4375734435258319 0.810553509585929 0.3892717426411517 4.500469025939774
  position -16.706176126405534 24.07385684037328 2.0668169539690133
}
TexturedBackground {
}
TexturedBackgroundLight {
}
RectangleArena {
  rotation 0 1 0 4.692820414042842e-06
  floorSize 10 10
}
Wall {
  translation -2.59 0.500002 -4.99
  rotation 0.5773509358554485 -0.5773489358556708 -0.5773509358554485 2.09439
  name "wall(9)"
}
Wall {
  translation -2.59 0.500002 -0.59
  rotation 0.5773509358554485 -0.5773489358556708 -0.5773509358554485 2.09439
  name "wall(11)"
}
Wall {
  translation -2.59 0.500002 1.71
  rotation 7.808799999990298e-07 1.3692899999982986e-06 -0.9999999999987577 1.5707953071795862
  name "wall(8)"
}
PottedTree {
  translation 4.1 0 4.34
  name "potted tree(1)"
}
Sofa {
  translation 3.24639 1.64588e-05 -3.50705
  rotation -9.719109999968656e-07 0.999999999996775 2.346399999992433e-06 -2.3561953071795863
}
PottedTree {
  translation 4.1 0 -4.3
}
AdvertisingBoard {
  translation 4.92 1.58 -0.820011
  rotation 2.3464099999870814e-06 0.9999999999944944 2.3464099999870814e-06 1.5708
}
Desk {
  translation 0.409998 9.80815e-06 -2.09
  rotation 2.3463999999870816e-06 0.9999999999944944 2.3463999999870816e-06 1.5708
  name "desk(3)"
}
Robot {
  translation 3.748918474847446 0.10471333790189377 3.809215102732457
  rotation -0.00019937463910245026 0.9999999764991317 -8.515567459685183e-05 1.450339225524495
  children [
    InertialUnit {
      rotation -1 0 0 1.5708
    }
    GPS {
    }
    SickLms291 {
      translation 0 0.15 0
      rotation -0.0026073289594429508 0.9999966009120719 -3.4468886243836845e-09 -5.307179586466759e-06
      noise 0.1
    }
    HingeJoint {
      jointParameters HingeJointParameters {
        position 10277.77115308211
        axis 0 1 0
        anchor 0 -0.09 -0.23
      }
      endPoint Solid {
        translation 0 -0.09 -0.23
        rotation 0 -1 0 1.52000946369279
        children [
          Shape {
            appearance Appearance {
            }
            geometry Sphere {
              radius 0.02
            }
          }
        ]
        name "solid(3)"
        boundingObject Sphere {
          radius 0.02
        }
        physics Physics {
        }
        linearVelocity -1.98621355463578e-07 -4.894483610404331e-06 -5.058941274212565e-06
        angularVelocity -0.0004695039571505376 5.141553093253663 -0.0013796902339986486
      }
    }
    HingeJoint {
      jointParameters HingeJointParameters {
        position -13177.7771538162
        axis 0 1 0
        anchor 0 -0.09 0.23
      }
      endPoint Solid {
        translation 0 -0.09 0.23
        rotation 0 1 0 4.345620646572785
        children [
          Shape {
            appearance Appearance {
            }
            geometry Sphere {
              radius 0.02
            }
          }
        ]
        name "solid(2)"
        boundingObject Sphere {
          radius 0.02
        }
        physics Physics {
        }
        linearVelocity 9.800924990556318e-08 4.886085414411691e-06 2.540438085438782e-06
        angularVelocity 0.0002780099369809719 -3.12111914651307 0.0008733897018413136
      }
    }
    DEF left_wheel HingeJoint {
      jointParameters HingeJointParameters {
        position -67.74418076031084
        axis 2 0 0
        anchor 0.31 0 0
      }
      device [
        RotationalMotor {
          name "left_motor"
        }
      ]
      endPoint Solid {
        translation 0.3100016733105416 0.00012485421512769583 0.000616113294373737
        rotation -0.647714583019024 -0.6477139913102582 -0.40116381243256016 2.378577439258004
        children [
          Shape {
            appearance Appearance {
              material Material {
              }
            }
            geometry Cylinder {
              height 0.08
              radius 0.12
            }
          }
        ]
        boundingObject Cylinder {
          height 0.08
          radius 0.12
        }
        physics Physics {
        }
        linearVelocity 2.530215177146079e-06 -4.829262173564713e-07 -2.0928844633140116e-06
        angularVelocity -3.945582634756274e-06 -1.0672123875860542e-05 2.092090855718695e-05
      }
    }
    DEF right_wheel HingeJoint {
      jointParameters HingeJointParameters {
        position -120.39885628916772
        axis 2 0 0
        anchor -0.31 0 0
      }
      device [
        RotationalMotor {
          name "right_motor"
        }
      ]
      endPoint Solid {
        translation -0.31 0 0
        rotation -0.6577123910842922 -0.6577173769806013 0.3671815118329637 3.84538515103298
        children [
          Shape {
            appearance Appearance {
              material Material {
              }
            }
            geometry Cylinder {
              height 0.08
              radius 0.12
            }
          }
        ]
        name "solid(1)"
        boundingObject Cylinder {
          height 0.08
          radius 0.12
        }
        physics Physics {
        }
        linearVelocity -2.4457173014961526e-06 4.86385983074005e-07 4.2870403014754925e-07
        angularVelocity -4.519380159557813e-06 -1.0688184001077473e-05 2.103744909410659e-05
      }
    }
    DEF body Shape {
      appearance Appearance {
        material Material {
          diffuseColor 0.913725 0.72549 0.431373
        }
      }
      geometry Box {
        size 0.5 0.15 0.5
      }
    }
  ]
  boundingObject USE body
  physics Physics {
  }
  controller "ros"
  controllerArgs [
    "--use-sim-time"
    "--clock"
    "--name=robot"
  ]
  linearVelocity -9.545159715202594e-07 -4.674860780748229e-09 -1.2358512331174393e-06
  angularVelocity -4.181907528277001e-06 -1.0663094116710013e-05 2.1125317617112656e-05
}
Wall {
  translation -5 0.5 -5
  rotation -0.5773509358554485 0.5773489358556708 0.5773509358554485 -2.094395307179586
  size 1 10 0.2
}
Wall {
  translation 5 0.5 -5
  rotation -0.5773509358554485 0.5773489358556708 0.5773509358554485 -2.094395307179586
  name "wall(1)"
  size 1 10 0.2
}
Wall {
  translation -5 0.5 -5
  rotation -7.8088e-07 -1.36929e-06 1 -1.5707953071795862
  name "wall(2)"
  size 1 10 0.2
}
Wall {
  translation -5 0.5 5
  rotation -7.8088e-07 -1.36929e-06 1 -1.5707953071795862
  name "wall(3)"
  size 1 10 0.2
}
Wall {
  translation 2.66 0.500002 1.71
  rotation -7.8088e-07 -1.36929e-06 1 -1.5707953071795862
  name "wall(4)"
}
Wall {
  translation 0.48 0.500002 1.71
  rotation -7.8088e-07 -1.36929e-06 1 -1.5707953071795862
  name "wall(5)"
}
Wall {
  translation -1.71 0.500002 1.71
  rotation -7.8088e-07 -1.36929e-06 1 -1.5707953071795862
  name "wall(6)"
}
Wall {
  translation -2.59 0.500002 1.71
  rotation -7.8088e-07 -1.36929e-06 1 -1.5707953071795862
  name "wall(7)"
}
WoodenChair {
  translation 0.020016 0 -2.12
  rotation 0 1 0 1.5708
  name "wooden chair(5)"
}
